7
Traceback (most recent call last):
  File "get_interaction_pair_two_dataset.py", line 3, in <module>
    import pandas as pd
  File "/new-stg/home/cong/miniconda3/envs/dpi/lib/python3.7/site-packages/pandas/__init__.py", line 50, in <module>
    from pandas.core.api import (
  File "/new-stg/home/cong/miniconda3/envs/dpi/lib/python3.7/site-packages/pandas/core/api.py", line 29, in <module>
    from pandas.core.arrays import Categorical
  File "/new-stg/home/cong/miniconda3/envs/dpi/lib/python3.7/site-packages/pandas/core/arrays/__init__.py", line 11, in <module>
    from pandas.core.arrays.interval import IntervalArray
  File "/new-stg/home/cong/miniconda3/envs/dpi/lib/python3.7/site-packages/pandas/core/arrays/interval.py", line 82, in <module>
    from pandas.core.indexes.base import ensure_index
  File "/new-stg/home/cong/miniconda3/envs/dpi/lib/python3.7/site-packages/pandas/core/indexes/base.py", line 21, in <module>
    from pandas._libs import (
ImportError: /new-stg/home/cong/miniconda3/envs/dpi/lib/python3.7/site-packages/pandas/_libs/index.cpython-37m-x86_64-linux-gnu.so: failed to map segment from shared object
